{
  "modified": "0001-01-01T00:00:00Z",
  "published": "2017-05-29T00:00:00Z",
  "schema_version": "1.5.0",
  "id": "PSF-2017-9",
  "summary": "bpo-30500: urllib connects to a wrong host",
  "details": "The urllib module doesn't parse correctly password containing the ``#``\ncharacter.\n",
  "affected": [
    {
      "ranges": [
        {
          "type": "GIT",
          "events": [
            {
              "introduced": "0"
            },
            {
              "fixed": "052f9d6860c48c5abcff8e16212e77cf4249d66c"
            },
            {
              "fixed": "4899d847ed3f56b2a712799f896aa1f28540a5c0"
            },
            {
              "fixed": "90e01e50ef8a9e6c91f30d965563c378a4ad26de"
            },
            {
              "fixed": "b0fba8874a4bd6bf4773e6efdbd8fa762e9f05bd"
            },
            {
              "fixed": "cc54c1c0d2d05fe7404ba64c53df4b1352ed2262"
            },
            {
              "fixed": "d4324baca4c03eb8d55446cd1b74b32ec5633af5"
            }
          ],
          "repo": "https://github.com/python/cpython"
        }
      ]
    }
  ],
  "references": [
    {
      "type": "REPORT",
      "url": "https://bugs.python.org/issue30500"
    }
  ],
  "database_specific": {
    "cwe_ids": []
  }
}
