{
  "modified": "2023-08-24T00:00:00Z",
  "published": "2023-08-24T00:00:00Z",
  "schema_version": "1.5.0",
  "id": "PSF-0000-CVE-2022-48566",
  "aliases": [
    "CVE-2022-48566",
    "GHSA-cgfh-jp5w-8cmx"
  ],
  "summary": "hmac.compare_digest() accumulator not constant-time",
  "details": "An issue was discovered in compare_digest in Lib/hmac.py in Python through 3.9.1. Constant-time-defeating optimisations were possible in the accumulator variable in hmac.compare_digest.",
  "affected": [
    {
      "ranges": [
        {
          "type": "GIT",
          "events": [
            {
              "introduced": "0"
            },
            {
              "fixed": "31729366e2bc09632e78f3896dbce0ae64914f28"
            },
            {
              "fixed": "c1bbca5b004b3f74d240ef8a76ff445cc1a27efb"
            },
            {
              "fixed": "97136d71a78a4b6b816f7e14acc52be426efcb6f"
            },
            {
              "fixed": "db95802bdfac4d13db3e2a391ec7b9e2f8d92dbe"
            },
            {
              "fixed": "8bef9ebb1b88cfa4b2a38b93fe4ea22015d8254a"
            }
          ],
          "repo": "https://github.com/python/cpython"
        },
        {
          "type": "ECOSYSTEM",
          "events": [
            {
              "introduced": "0"
            },
            {
              "fixed": "3.6.13"
            },
            {
              "introduced": "3.7.0"
            },
            {
              "fixed": "3.7.10"
            },
            {
              "introduced": "3.8.0"
            },
            {
              "fixed": "3.8.7"
            },
            {
              "introduced": "3.9.0"
            },
            {
              "fixed": "3.9.1"
            },
            {
              "introduced": "3.10.0a1"
            },
            {
              "fixed": "3.10.0a3"
            }
          ]
        }
      ]
    }
  ],
  "references": [
    {
      "type": "ADVISORY",
      "url": "https://nvd.nist.gov/vuln/detail/CVE-2022-48566"
    },
    {
      "type": "WEB",
      "url": "https://bugs.python.org/issue40791"
    }
  ]
}
